<?xml version="1.0" ?><!-- =================================================================================== --><!-- |    This document was autogenerated by xacro from /home/panzer/catkin_ws/install/rozum_pulse_75/share/rozum_pulse_75/urdf/rozum_pulse_75.xacro | --><!-- |    EDITING THIS FILE BY HAND IS NOT RECOMMENDED                                 | --><!-- =================================================================================== --><!-- This URDF was automatically created by SolidWorks to URDF Exporter! Originally created by Stephen Brawner (brawner@gmail.com) 
     Commit Version: 1.6.0-4-g7f85cfe  Build Version: 1.6.7995.38578
     For more information, please see http://wiki.ros.org/sw_urdf_exporter --><robot name="rozum_pulse_75"><transmission name="left_outer_knuckle_joint_trans"><type>transmission_interface/SimpleTransmission</type><joint name="left_outer_knuckle_joint"><hardwareInterface>hardware_interface/EffortJointInterface</hardwareInterface></joint><actuator name="left_outer_knuckle_joint_motor"><mechanicalReduction>1</mechanicalReduction><hardwareInterface>hardware_interface/EffortJointInterface</hardwareInterface></actuator></transmission><!-- <xacro:ag95_gazebo prefix="${prefix}" /> --><!-- base link flange --><link name="ag95_base_link"><!-- <inertial>
        <origin xyz="7.892486664218268e-13 9.73814800116557e-05 0.0030311891257515876" rpy="0 0 0" />
        <mass value="0.18321316702693136" />
        <inertia ixx="4e-05" iyy="0.000121" izz="0.000158" ixy="0.0" iyz="0.0" ixz="-0.0" />
      </inertial> --><inertial><origin rpy="0 0 0" xyz="7.892486664218268e-13 9.73814800116557e-05 0.0030311891257515876"/><mass value="0.05335674905975589"/><inertia ixx="1.1649107960000001e-05" ixy="0.0" ixz="-0.0" iyy="3.5238551579e-05" iyz="0.0" izz="4.6013976442e-05"/></inertial><visual><origin rpy="0 0 0" xyz="0 0 0"/><geometry><mesh filename="package://rozum_pulse_75/meshes/gripper/visual/base_link.stl" scale="0.001 0.001 0.001"/></geometry><material name=""><color rgba="0.792156862745098 0.819607843137255 0.933333333333333 1"/></material></visual><collision><origin rpy="0 0 0" xyz="0 0 0"/><geometry><mesh filename="package://rozum_pulse_75/meshes/gripper/collision/base_link.stl" scale="0.001 0.001 0.001"/></geometry></collision></link><!-- main body of gripper --><link name="ag95_body"><!-- <inertial>
        <origin xyz="0.040363309423792425 0.014263796342398428 0.04377145101823153" rpy="0 0 0" />
        <mass value="2.681074820833332" />
        <inertia ixx="0.003857" iyy="0.004463" izz="0.001562" ixy="-3e-06" iyz="-2e-06" ixz="-9e-06" />
      </inertial> --><inertial><origin rpy="0 0 0" xyz="0.040363309423792425 0.014263796342398428 0.04377145101823153"/><mass value="0.7808032509181286"/><inertia ixx="0.001123265235043" ixy="-8.736830970000001e-07" ixz="-2.621049291e-06" iyy="0.001299749220637" iyz="-5.82455398e-07" izz="0.00045489766583800003"/></inertial><visual><origin rpy="0 0 0" xyz="0.0405 0.0143 -0.0147"/><geometry><mesh filename="package://rozum_pulse_75/meshes/gripper/visual/gripper_body.stl" scale="0.001 0.001 0.001"/></geometry><material name=""><color rgba="0.1 0.1 0.1 1"/></material></visual><collision><origin rpy="0 0 0" xyz="0.0405 0.0143 -0.0147"/><geometry><mesh filename="package://rozum_pulse_75/meshes/gripper/collision/gripper_body.stl" scale="0.001 0.001 0.001"/></geometry></collision></link><joint name="ag95_body_joint" type="fixed"><origin rpy="0 0 0" xyz="-0.0405 -0.0143 0.0147"/><parent link="ag95_base_link"/><child link="ag95_body"/></joint><link name="left_outer_knuckle"><inertial><origin rpy="0 0 0" xyz="0.027678515816713697 0.008750002359538555 -4.432690447753185e-07"/><mass value="0.0589066057773107"/><inertia ixx="1e-06" ixy="0.0" ixz="-0.0" iyy="1.7e-05" iyz="0.0" izz="1.7e-05"/></inertial><!-- <inertial>
          <origin xyz="0.027678515816713697 0.008750002359538555 -4.432690447753185e-07" rpy="0 0 0" />
          <mass value="${0.0589066057773107*0.44684369179}" />
          <inertia ixx="${1e-06*0.44684369179}" iyy="${1.7e-05*0.44684369179}" izz="${1.7e-05*0.44684369179}" ixy="${0.0*0.44684369179}" iyz="${0.0*0.44684369179}" ixz="${-0.0*0.44684369179}" />
        </inertial> --><visual><origin rpy="0 0 0" xyz="-0.036673 0.00875 -0.098336"/><geometry><mesh filename="package://rozum_pulse_75/meshes/gripper/visual/outer_knuckle.stl" scale="0.001 0.001 0.001"/></geometry><material name=""><color rgba="0.1 0.1 0.1 1"/></material></visual><collision><origin rpy="0 0 0" xyz="-0.036673 0.00875 -0.098336"/><geometry><mesh filename="package://rozum_pulse_75/meshes/gripper/collision/outer_knuckle.stl" scale="0.001 0.001 0.001"/></geometry></collision></link><link name="left_inner_knuckle"><inertial><origin rpy="0 0 0" xyz="-0.001773347637755853 0.025399999999162655 0.028950024725163018"/><mass value="0.07116672022913799"/><inertia ixx="3.7e-05" ixy="0.0" ixz="0.0" iyy="1.7e-05" iyz="-0.0" izz="2.1e-05"/></inertial><!-- <inertial>
          <origin xyz="-0.001773347637755853 0.025399999999162655 0.028950024725163018" rpy="0 0 0" />
          <mass value="${0.07116672022913799*0.44684369179}" />
          <inertia ixx="${3.7e-05*0.44684369179}" iyy="${1.7e-05*0.44684369179}" izz="${2.1e-05*0.44684369179}" ixy="${0.0*0.44684369179}" iyz="${-0.0*0.44684369179}" ixz="${0.0*0.44684369179}" />
        </inertial> --><visual><origin rpy="0 0 0" xyz="-0.016 0.0254 -0.10586"/><geometry><mesh filename="package://rozum_pulse_75/meshes/gripper/visual/inner_knuckle.stl" scale="0.001 0.001 0.001"/></geometry><material name=""><color rgba="0.1 0.1 0.1 1"/></material></visual><collision><origin rpy="0 0 0" xyz="-0.016 0.0254 -0.10586"/><geometry><mesh filename="package://rozum_pulse_75/meshes/gripper/collision/inner_knuckle.stl" scale="0.001 0.001 0.001"/></geometry></collision></link><link name="left_finger"><inertial><origin rpy="0 0 0" xyz="-0.013763205176003518 0.008750002316393751 0.007315452388518454"/><mass value="0.035304126564626004"/><inertia ixx="2e-06" ixy="0.0" ixz="1e-06" iyy="4e-06" iyz="-0.0" izz="3e-06"/></inertial><!-- <inertial>
          <origin xyz="-0.013763205176003518 0.008750002316393751 0.007315452388518454" rpy="0 0 0" />
          <mass value="${0.035304126564626004*0.14953484502}" />
          <inertia ixx="${2e-06*0.14953484502}" iyy="${4e-06*0.14953484502}" izz="${3e-06*0.14953484502}" ixy="${0.0*0.14953484502}" iyz="${-0.0*0.14953484502}" ixz="${1e-06*0.14953484502}" />
        </inertial> --><visual><origin rpy="0 0 0" xyz="-0.091673 0.00875 -0.098336"/><geometry><mesh filename="package://rozum_pulse_75/meshes/gripper/visual/finger.stl" scale="0.001 0.001 0.001"/></geometry><material name=""><color rgba="0.1 0.1 0.1 1"/></material></visual><collision><origin rpy="0 0 0" xyz="-0.091673 0.00875 -0.098336"/><geometry><mesh filename="package://rozum_pulse_75/meshes/gripper/collision/finger.stl" scale="0.001 0.001 0.001"/></geometry></collision></link><link name="left_finger_pad"><inertial><origin rpy="0 0 0" xyz="-0.0022695421476374017 2.3166990085415594e-09 0.00779073905191241"/><mass value="0.047823655444711066"/><inertia ixx="5e-06" ixy="-0.0" ixz="0.0" iyy="4e-06" iyz="0.0" izz="2e-06"/></inertial><!-- <inertial>
          <origin xyz="-0.0022695421476374017 2.3166990085415594e-09 0.00779073905191241"
            rpy="0 0 0" />
          <mass value="${0.047823655444711066*0.14953484502}" />
          <inertia ixx="${5e-06*0.14953484502}" iyy="${4e-06*0.14953484502}" izz="${2e-06*0.14953484502}" ixy="${-0.0*0.14953484502}" iyz="${0.0*0.14953484502}" ixz="${0.0*0.14953484502}" />
        </inertial> --><visual><origin rpy="0 0 0" xyz="-0.0705 -0.0 -0.12056"/><geometry><mesh filename="package://rozum_pulse_75/meshes/gripper/visual/finger_pad.stl" scale="0.001 0.001 0.001"/></geometry><material name=""><color rgba="0.792156862745098 0.819607843137255 0.933333333333333 1"/></material></visual><collision><origin rpy="0 0 0" xyz="-0.0705 -0.0 -0.12056"/><geometry><mesh filename="package://rozum_pulse_75/meshes/gripper/collision/finger_pad.stl" scale="0.001 0.001 0.001"/></geometry></collision></link><joint name="left_finger_joint" type="revolute"><origin rpy="0 0.7800050960087859 0" xyz="0.055 0.0 0.0"/><parent link="left_outer_knuckle"/><child link="left_finger"/><axis xyz="0.0 1.0 -0.0"/><limit effort="50.0" lower="-0.01" upper="0.9400000000000001" velocity="2.0"/><mimic joint="left_outer_knuckle_joint" multiplier="1" offset="0"/></joint><joint name="left_inner_knuckle_joint" type="revolute"><origin rpy="0 0.7907912307861107 0.0" xyz="0.0565 -0.0111 0.09116"/><parent link="ag95_body"/><child link="left_inner_knuckle"/><axis xyz="0.0 -1.0 -0.0"/><limit effort="50.0" lower="-0.01" upper="0.9400000000000001" velocity="2.0"/><mimic joint="left_outer_knuckle_joint" multiplier="1" offset="0"/></joint><!-- This joint closes the kinematic loop. Since loops are not allowed in URDF, but they are
      allowed in SDF, this is an SDF fragment. --><gazebo><joint name="left_inner_knuckle_to_finger_joint" type="revolute"><pose> -0.020673 0 0.007524 0 0 0</pose><axis><xyz>0 1 0</xyz><use_parent_model_frame>false</use_parent_model_frame></axis><parent>left_inner_knuckle</parent><child>left_finger</child></joint></gazebo><joint name="left_inner_finger_pad_joint" type="fixed"><origin rpy="0 0 0" xyz="-0.021173 0.00875 0.022224"/><parent link="left_finger"/><child link="left_finger_pad"/></joint><joint name="left_outer_knuckle_joint" type="revolute"><origin rpy="0 -0.7800050960087859 0" xyz="0.077173 0.00555 0.083636"/><parent link="ag95_body"/><child link="left_outer_knuckle"/><axis xyz="-0.0 -1.0 0.0"/><limit effort="50.0" lower="0" upper="0.93" velocity="2.0"/></joint><joint name="right_finger_joint" type="revolute"><origin rpy="0 0.7800050960087859 0" xyz="0.055 0.0 0.0"/><parent link="right_outer_knuckle"/><child link="right_finger"/><axis xyz="0.0 1.0 -0.0"/><limit effort="50.0" lower="-0.01" upper="0.9400000000000001" velocity="2.0"/><mimic joint="left_outer_knuckle_joint" multiplier="1" offset="0"/></joint><joint name="right_inner_knuckle_joint" type="revolute"><origin rpy="0 0.7907912307861107 -3.141592653589793" xyz="0.0245 0.0397 0.09116"/><parent link="ag95_body"/><child link="right_inner_knuckle"/><axis xyz="0.0 -1.0 -0.0"/><limit effort="50.0" lower="-0.01" upper="0.9400000000000001" velocity="2.0"/><mimic joint="left_outer_knuckle_joint" multiplier="1" offset="0"/></joint><!-- This joint closes the kinematic loop. Since loops are not allowed in URDF, but they are
      allowed in SDF, this is an SDF fragment. --><gazebo><joint name="right_inner_knuckle_to_finger_joint" type="revolute"><pose> -0.020673 0 0.007524 0 0 0</pose><axis><xyz>0 1 0</xyz><use_parent_model_frame>false</use_parent_model_frame></axis><parent>right_inner_knuckle</parent><child>right_finger</child></joint></gazebo><joint name="right_inner_finger_pad_joint" type="fixed"><origin rpy="0 0 0" xyz="-0.021173 0.00875 0.022224"/><parent link="right_finger"/><child link="right_finger_pad"/></joint><link name="right_outer_knuckle"><inertial><origin rpy="0 0 0" xyz="0.027678515816713697 0.008750002359538555 -4.432690447753185e-07"/><mass value="0.0589066057773107"/><inertia ixx="1e-06" ixy="0.0" ixz="-0.0" iyy="1.7e-05" iyz="0.0" izz="1.7e-05"/></inertial><!-- <inertial>
          <origin xyz="0.027678515816713697 0.008750002359538555 -4.432690447753185e-07" rpy="0 0 0" />
          <mass value="${0.0589066057773107*0.44684369179}" />
          <inertia ixx="${1e-06*0.44684369179}" iyy="${1.7e-05*0.44684369179}" izz="${1.7e-05*0.44684369179}" ixy="${0.0*0.44684369179}" iyz="${0.0*0.44684369179}" ixz="${-0.0*0.44684369179}" />
        </inertial> --><visual><origin rpy="0 0 0" xyz="-0.036673 0.00875 -0.098336"/><geometry><mesh filename="package://rozum_pulse_75/meshes/gripper/visual/outer_knuckle.stl" scale="0.001 0.001 0.001"/></geometry><material name=""><color rgba="0.1 0.1 0.1 1"/></material></visual><collision><origin rpy="0 0 0" xyz="-0.036673 0.00875 -0.098336"/><geometry><mesh filename="package://rozum_pulse_75/meshes/gripper/collision/outer_knuckle.stl" scale="0.001 0.001 0.001"/></geometry></collision></link><link name="right_inner_knuckle"><inertial><origin rpy="0 0 0" xyz="-0.001773347637755853 0.025399999999162655 0.028950024725163018"/><mass value="0.07116672022913799"/><inertia ixx="3.7e-05" ixy="0.0" ixz="0.0" iyy="1.7e-05" iyz="-0.0" izz="2.1e-05"/></inertial><!-- <inertial>
          <origin xyz="-0.001773347637755853 0.025399999999162655 0.028950024725163018" rpy="0 0 0" />
          <mass value="${0.07116672022913799*0.44684369179}" />
          <inertia ixx="${3.7e-05*0.44684369179}" iyy="${1.7e-05*0.44684369179}" izz="${2.1e-05*0.44684369179}" ixy="${0.0*0.44684369179}" iyz="${-0.0*0.44684369179}" ixz="${0.0*0.44684369179}" />
        </inertial> --><visual><origin rpy="0 0 0" xyz="-0.016 0.0254 -0.10586"/><geometry><mesh filename="package://rozum_pulse_75/meshes/gripper/visual/inner_knuckle.stl" scale="0.001 0.001 0.001"/></geometry><material name=""><color rgba="0.1 0.1 0.1 1"/></material></visual><collision><origin rpy="0 0 0" xyz="-0.016 0.0254 -0.10586"/><geometry><mesh filename="package://rozum_pulse_75/meshes/gripper/collision/inner_knuckle.stl" scale="0.001 0.001 0.001"/></geometry></collision></link><link name="right_finger"><inertial><origin rpy="0 0 0" xyz="-0.013763205176003518 0.008750002316393751 0.007315452388518454"/><mass value="0.035304126564626004"/><inertia ixx="2e-06" ixy="0.0" ixz="1e-06" iyy="4e-06" iyz="-0.0" izz="3e-06"/></inertial><!-- <inertial>
          <origin xyz="-0.013763205176003518 0.008750002316393751 0.007315452388518454" rpy="0 0 0" />
          <mass value="${0.035304126564626004*0.14953484502}" />
          <inertia ixx="${2e-06*0.14953484502}" iyy="${4e-06*0.14953484502}" izz="${3e-06*0.14953484502}" ixy="${0.0*0.14953484502}" iyz="${-0.0*0.14953484502}" ixz="${1e-06*0.14953484502}" />
        </inertial> --><visual><origin rpy="0 0 0" xyz="-0.091673 0.00875 -0.098336"/><geometry><mesh filename="package://rozum_pulse_75/meshes/gripper/visual/finger.stl" scale="0.001 0.001 0.001"/></geometry><material name=""><color rgba="0.1 0.1 0.1 1"/></material></visual><collision><origin rpy="0 0 0" xyz="-0.091673 0.00875 -0.098336"/><geometry><mesh filename="package://rozum_pulse_75/meshes/gripper/collision/finger.stl" scale="0.001 0.001 0.001"/></geometry></collision></link><link name="right_finger_pad"><inertial><origin rpy="0 0 0" xyz="-0.0022695421476374017 2.3166990085415594e-09 0.00779073905191241"/><mass value="0.047823655444711066"/><inertia ixx="5e-06" ixy="-0.0" ixz="0.0" iyy="4e-06" iyz="0.0" izz="2e-06"/></inertial><!-- <inertial>
          <origin xyz="-0.0022695421476374017 2.3166990085415594e-09 0.00779073905191241"
            rpy="0 0 0" />
          <mass value="${0.047823655444711066*0.14953484502}" />
          <inertia ixx="${5e-06*0.14953484502}" iyy="${4e-06*0.14953484502}" izz="${2e-06*0.14953484502}" ixy="${-0.0*0.14953484502}" iyz="${0.0*0.14953484502}" ixz="${0.0*0.14953484502}" />
        </inertial> --><visual><origin rpy="0 0 0" xyz="-0.0705 -0.0 -0.12056"/><geometry><mesh filename="package://rozum_pulse_75/meshes/gripper/visual/finger_pad.stl" scale="0.001 0.001 0.001"/></geometry><material name=""><color rgba="0.792156862745098 0.819607843137255 0.933333333333333 1"/></material></visual><collision><origin rpy="0 0 0" xyz="-0.0705 -0.0 -0.12056"/><geometry><mesh filename="package://rozum_pulse_75/meshes/gripper/collision/finger_pad.stl" scale="0.001 0.001 0.001"/></geometry></collision></link><joint name="right_outer_knuckle_joint" type="revolute"><origin rpy="0 -0.7800050960087859 3.141592653589793" xyz="0.003827000000000011 0.02305 0.083636"/><parent link="ag95_body"/><child link="right_outer_knuckle"/><axis xyz="-0.0 -1.0 0.0"/><limit effort="50.0" lower="-0.01" upper="0.9400000000000001" velocity="2.0"/><mimic joint="left_outer_knuckle_joint" multiplier="1" offset="0"/></joint><joint name="gripper_base_joint" type="fixed"><parent link="gripper_base"/><child link="ag95_base_link"/><origin rpy="0 0 0" xyz="0 0 -0.0078"/></joint><link name="gripper_base"/><gazebo><plugin filename="libgazebo_ros_control.so" name="ros_control"/></gazebo><link name="base_link"><inertial><origin rpy="0 0 0" xyz="0.0 0.0 0.0"/><mass value="0.000000"/><inertia ixx="0.000000" ixy="0.000000" ixz="0.000000" iyy="0.000000" iyz="0.000000" izz="0.000000"/></inertial><visual><origin rpy="0 0 0" xyz="0 0 0"/><geometry><mesh filename="package://rozum_pulse_75/meshes/manipulator/base_link.STL"/></geometry><material name=""><color rgba="0.79216 0.81961 0.93333 1"/></material></visual><collision><origin rpy="0 0 0" xyz="0 0 0"/><geometry><mesh filename="package://rozum_pulse_75/meshes/manipulator/base_link.STL"/></geometry></collision></link><link name="world"/><joint name="world_joint" type="fixed"><origin rpy="0 0 0" xyz="0 0 0"/><parent link="world"/><child link="base_link"/></joint><link name="link1_dummy"/><joint name="joint1" type="revolute"><origin rpy="0 0 0" xyz="0.0 0.0 0.0"/><motor_params gear_ratio="100" rotor_inertia="0.000108"/><parent link="base_link"/><child link="link1_dummy"/><axis xyz="0 0 1"/><limit effort="10" lower="-6.28" upper="6.28" velocity="10"/></joint><link name="link1"><inertial><origin rpy="0 0 0" xyz="0.000000 -0.048113 -0.005173"/><mass value="2.635479"/><inertia ixx="0.00574463" ixy="0.00000001" ixz="0.000000" iyy="0.00314996" iyz="-0.0006622" izz="0.00545542"/></inertial><visual><origin rpy="0 0 0" xyz="0 0 0"/><geometry><mesh filename="package://rozum_pulse_75/meshes/manipulator/link1.STL"/></geometry><material name=""><color rgba="1 1 1 1"/></material></visual><collision><origin rpy="0 0 0" xyz="0 0 0"/><geometry><mesh filename="package://rozum_pulse_75/meshes/manipulator/link1.STL"/></geometry></collision></link><joint name="joint1_post_transform" type="fixed"><origin rpy="1.5707963 0 0" xyz="0.0 0.0 0.215"/><motor_params gear_ratio="100" rotor_inertia="0.000108"/><parent link="link1_dummy"/><child link="link1"/><axis xyz="0 0 1"/><limit effort="10" lower="-6.28" upper="6.28" velocity="10"/></joint><link name="link2_dummy"/><joint name="joint2" type="revolute"><origin rpy="0 0 0" xyz="0.0 0.0 0.0"/><motor_params gear_ratio="100" rotor_inertia="0.000108"/><parent link="link1"/><child link="link2_dummy"/><axis xyz="0 0 1"/><limit effort="10" lower="-0.6108652382" upper="3.76991118431" velocity="10"/></joint><link name="link2"><inertial><origin rpy="0 0 0" xyz="-0.18221343 0.000000 0.09945403"/><mass value="2.03639714"/><inertia ixx="0.00328492" ixy="0.000000" ixz="0.00467611" iyy="0.03067676" iyz="0.000000" izz="0.02924741"/></inertial><visual><origin rpy="0 0 0" xyz="0.0 0.0 0.0"/><geometry><mesh filename="package://rozum_pulse_75/meshes/manipulator/link2.STL"/></geometry><material name=""><color rgba="0.24314 0.24314 0.24314 1"/></material></visual><collision><origin rpy="0 0 0" xyz="0.0 0.0 0.0"/><geometry><mesh filename="package://rozum_pulse_75/meshes/manipulator/link2.STL"/></geometry></collision></link><joint name="joint2_post_transform" type="fixed"><origin rpy="0 0 0" xyz="-0.286 -0.0 0.119"/><motor_params gear_ratio="100" rotor_inertia="0.000108"/><parent link="link2_dummy"/><child link="link2"/><axis xyz="0 0 1"/><limit effort="10" lower="-0.6108652382" upper="3.76991118431" velocity="10"/></joint><link name="link3_dummy"/><joint name="joint3" type="revolute"><origin rpy="0 0 0" xyz="0.0 0.0 0.0"/><motor_params gear_ratio="100" rotor_inertia="0.000170"/><parent link="link2"/><child link="link3_dummy"/><axis xyz="0 0 1"/><limit effort="10" lower="-2.79252680319" upper="2.79252680319" velocity="10"/></joint><link name="link3"><inertial><origin rpy="0 0 0" xyz="-0.19839838 0.000000 0.04913607"/><mass value="1.60265591"/><inertia ixx="0.00237088" ixy="-0.00000001" ixz="-0.0027249" iyy="0.01624523" iyz="0.00000000" izz="0.01492074"/></inertial><visual><origin rpy="0 0 0" xyz="0.0 0.0 0.0"/><geometry><mesh filename="package://rozum_pulse_75/meshes/manipulator/link3.STL"/></geometry><material name=""><color rgba="0.24314 0.24314 0.24314 1"/></material></visual><collision><origin rpy="0 0 0" xyz="0.0 0.0 0.0"/><geometry><mesh filename="package://rozum_pulse_75/meshes/manipulator/link3.STL"/></geometry></collision></link><joint name="joint3_post_transform" type="fixed"><origin rpy="0 0 0" xyz="-0.26 -0.0 -0.093"/><parent link="link3_dummy"/><child link="link3"/></joint><link name="link4_dummy"/><joint name="joint4" type="revolute"><origin rpy="0 0 0" xyz="0.0 0.0 0.0"/><motor_params gear_ratio="100" rotor_inertia="0.000170"/><parent link="link3"/><child link="link4_dummy"/><axis xyz="0 0 1"/><limit effort="10" lower="-4.41568300755" upper="4.38077642251" velocity="10"/></joint><link name="link4"><inertial><origin rpy="0 0 0" xyz="0.000000 -0.07193817 0.1201976"/><mass value="0.83986351"/><inertia ixx="0.00167115" ixy="0.000000" ixz="0.000000" iyy="0.00037091" iyz="-0.00003977" izz="0.00171639"/></inertial><visual><origin rpy="0 0 0" xyz="0 0 0"/><geometry><mesh filename="package://rozum_pulse_75/meshes/manipulator/link4.STL"/></geometry><material name=""><color rgba="0.79216 0.81961 0.93333 1"/></material></visual><collision><origin rpy="0 0 0" xyz="0 0 0"/><geometry><mesh filename="package://rozum_pulse_75/meshes/manipulator/link4.STL"/></geometry></collision></link><joint name="joint4_post_transform" type="fixed"><origin rpy="1.5707963 0 0" xyz="0.0 0.0 0.093"/><motor_params gear_ratio="100" rotor_inertia="0.000170"/><parent link="link4_dummy"/><child link="link4"/><axis xyz="0 0 1"/><limit effort="10" lower="-4.41568300755" upper="4.38077642251" velocity="10"/></joint><link name="link5_dummy"/><joint name="joint5" type="revolute"><origin rpy="0 0 0" xyz="0.0 0.0 0.0"/><motor_params gear_ratio="100" rotor_inertia="0.000170"/><parent link="link4"/><child link="link5_dummy"/><axis xyz="0 0 1"/><limit effort="10" lower="-6.28" upper="6.28" velocity="10"/></joint><link name="link5"><inertial><origin rpy="0 0 0" xyz="0.000000 0.03592275 0.1667588"/><mass value="0.69108633"/><inertia ixx="0.00074292" ixy="0" ixz="0" iyy="0.00029829" iyz="0.00007183" izz="0.00071953"/></inertial><visual><origin rpy="0 0 0" xyz="0 0 0"/><geometry><mesh filename="package://rozum_pulse_75/meshes/manipulator/link5.STL"/></geometry><material name=""><color rgba="0.18039 0.18039 0.18039 1"/></material></visual><collision><origin rpy="0 0 0" xyz="0 0 0"/><geometry><mesh filename="package://rozum_pulse_75/meshes/manipulator/link5.STL"/></geometry></collision></link><joint name="joint5_post_transform" type="fixed"><origin rpy="-1.5707963 0 0" xyz="0.0 0.0 0.1681"/><parent link="link5_dummy"/><child link="link5"/></joint><link name="link6_dummy"/><joint name="joint6" type="revolute"><origin rpy="0 0 0" xyz="0.0 0.0 0.0"/><motor_params gear_ratio="100" rotor_inertia="0.0000083"/><parent link="link5"/><child link="link6_dummy"/><axis xyz="0 0 1"/><limit effort="10" lower="-6.28" upper="6.28" velocity="10"/></joint><link name="link6"><inertial><origin rpy="0 0 0" xyz="0.00171740 -0.00095207 0.02"/><mass value="0.20018162"/><inertia ixx="0.00008258" ixy="-0.00000345" ixz="0.00000022" iyy="0.00007742" iyz="-0.00000061" izz="0.00011673"/></inertial><visual><origin rpy="0 0 0" xyz="0 0 0"/><geometry><mesh filename="package://rozum_pulse_75/meshes/manipulator/link6.STL"/></geometry><material name=""><color rgba="0.24314 0.24314 0.24314 1"/></material></visual><collision><origin rpy="0 0 0" xyz="0 0 0"/><geometry><mesh filename="package://rozum_pulse_75/meshes/manipulator/link6.STL"/></geometry></collision></link><joint name="joint6_post_transform" type="fixed"><origin rpy="0 0 0" xyz="0.0 0.0 0.1196"/><parent link="link6_dummy"/><child link="link6"/></joint><joint name="gripper_joint" type="fixed"><origin rpy="0 0 0" xyz="0.0 0.0 0.0"/><parent link="link6"/><child link="gripper_base"/></joint></robot>